Workbook

Sheet Data
A1: Week_Start | B1: Category | C1: Units_Sold | D1: Unit_Price_EUR | E1: Revenue_EUR | F1: Stock_Start | G1: Stock_End | H1: Supplier_Delay_Days | I1: Demand_Spike | J1: Out_of_Stock | K1: Notes | L1: Year | M1: Period
A2: 43472 | B2: Adult Productive Cough Syrup | C2: 29 | D2: 6.62 | E2: 191.98 | F2: 38 | G2: 14 | H2: 1 | I2: No | J2: No | L2: =YEAR(A2) -> 2019 | M2: =IF(L2=2019,"Pre-COVID","COVID Period") -> Pre-COVID
A3: 43472 | B3: Adult Dry Cough Syrup | C3: 21 | D3: 7.13 | E3: 149.73 | F3: 22 | G3: 3 | H3: 0.3 | I3: No | J3: No | L3: =YEAR(A3) -> 2019 | M3: =IF(L3=2019,"Pre-COVID","COVID Period") -> Pre-COVID
A4: 43472 | B4: Children's Productive Cough Syrup | C4: 9 | D4: 5.95 | E4: 53.55 | F4: 13 | G4: 5 | H4: 1.5 | I4: No | J4: No | L4: =YEAR(A4) -> 2019 | M4: =IF(L4=2019,"Pre-COVID","COVID Period") -> Pre-COVID
A5: 43472 | B5: Children's Dry Cough Syrup | C5: 15 | D5: 6.41 | E5: 96.15 | F5: 19 | G5: 4 | H5: 1.7 | I5: No | J5: No | L5: =YEAR(A5) -> 2019 | M5: =IF(L5=2019,"Pre-COVID","COVID Period") -> Pre-COVID
A6: 43472 | B6: Cough Lozenges | C6: 25 | D6: 3.29 | E6: 82.25 | F6: 35 | G6: 13 | H6: 0.8 | I6: No | J6: No | L6: =YEAR(A6) -> 2019 | M6: =IF(L6=2019,"Pre-COVID","COVID Period") -> Pre-COVID
A7: 43472 | B7: Antibiotic Prescriptions | C7: 13 | D7: 8.2 | E7: 106.6 | F7: 14 | G7: 3 | H7: 0.6 | I7: No | J7: No | L7: =YEAR(A7) -> 2019 | M7: =IF(L7=2019,"Pre-COVID","COVID Period") -> Pre-COVID
A8: 43472 | B8: Vitamins & Supplements | C8: 28 | D8: 11.96 | E8: 334.88 | F8: 38 | G8: 11 | H8: 0.4 | I8: No | J8: No | L8: =YEAR(A8) -> 2019 | M8: =IF(L8=2019,"Pre-COVID","COVID Period") -> Pre-COVID
A9: 43472 | B9: Simple Masks | C9: 9 | D9: 0.68 | E9: 6.12 | F9: 13 | G9: 6 | H9: 0.7 | I9: No | J9: No | L9: =YEAR(A9) -> 2019 | M9: =IF(L9=2019,"Pre-COVID","COVID Period") -> Pre-COVID
A10: 43472 | B10: KN95/FFP2 Masks | C10: 8 | D10: 1.36 | E10: 10.88 | F10: 12 | G10: 4 | H10: 0.5 | I10: No | J10: No | L10: =YEAR(A10) -> 2019 | M10: =IF(L10=2019,"Pre-COVID","COVID Period") -> Pre-COVID
A11: 43472 | B11: Antiseptic / Alcohol | C11: 6 | D11: 4.05 | E11: 24.3 | F11: 7 | G11: 2 | H11: 0.4 | I11: No | J11: No | L11: =YEAR(A11) -> 2019 | M11: =IF(L11=2019,"Pre-COVID","COVID Period") -> Pre-COVID
A12: 43472 | B12: Hand Gloves | C12: 4 | D12: 5.52 | E12: 22.08 | F12: 6 | G12: 3 | H12: 0.7 | I12: No | J12: No | L12: =YEAR(A12) -> 2019 | M12: =IF(L12=2019,"Pre-COVID","COVID Period") -> Pre-COVID
A13: 43472 | B13: COVID Self Tests | C13: 0 | D13: 5.03 | E13: 0 | F13: 3 | G13: 3 | H13: 0.7 | I13: No | J13: No | L13: =YEAR(A13) -> 2019 | M13: =IF(L13=2019,"Pre-COVID","COVID Period") -> Pre-COVID
... A38: 43486 | B38: Hand Gloves | C38: 4 | D38: 5.67 | E38: 22.68 | F38: 5 | G38: 1 | H38: 0.9 | I38: No | J38: No | L38: =YEAR(A38) -> 2019 | M38: =IF(L38=2019,"Pre-COVID","COVID Period") -> Pre-COVID
A39: 43486 | B39: COVID Self Tests | C39: 1 | D39: 4.86 | E39: 4.86 | F39: 3 | G39: 2 | H39: 0.8 | I39: Yes | J39: No | K39: COVID-related demand spike | L39: =YEAR(A39) -> 2019 | M39: =IF(L39=2019,"Pre-COVID","COVID Period") -> Pre-COVID
A40: 43486 | B40: Pharmacy COVID Test Service | C40: 1 | D40: 14.69 | E40: 14.69 | F40: 3 | G40: 3 | H40: 0.2 | I40: Yes | J40: No | L40: =YEAR(A40) -> 2019 | M40: =IF(L40=2019,"Pre-COVID","COVID Period") -> Pre-COVID
A41: 43493 | B41: Adult Productive Cough Syrup | C41: 17 | D41: 7.08 | E41: 120.36 | F41: 20 | G41: 5 | H41: 0.4 | I41: No | J41: No | L41: =YEAR(A41) -> 2019 | M41: =IF(L41=2019,"Pre-COVID","COVID Period") -> Pre-COVID
A42: 43493 | B42: Adult Dry Cough Syrup | C42: 22 | D42: 6.98 | E42: 153.56 | F42: 35 | G42: 18 | H42: 0.6 | I42: No | J42: No | L42: =YEAR(A42) -> 2019 | M42: =IF(L42=2019,"Pre-COVID","COVID Period") -> Pre-COVID
A43: 43493 | B43: Children's Productive Cough Syrup | C43: 12 | D43: 6.11 | E43: 73.32 | F43: 15 | G43: 5 | H43: 0.8 | I43: No | J43: No | L43: =YEAR(A43) -> 2019 | M43: =IF(L43=2019,"Pre-COVID","COVID Period") -> Pre-COVID
A44: 43493 | B44: Children's Dry Cough Syrup | C44: 13 | D44: 6.34 | E44: 82.42 | F44: 16 | G44: 4 | H44: 1.1 | I44: No | J44: No | L44: =YEAR(A44) -> 2019 | M44: =IF(L44=2019,"Pre-COVID","COVID Period") -> Pre-COVID
A45: 43493 | B45: Cough Lozenges | C45: 26 | D45: 3.21 | E45: 83.46 | F45: 37 | G45: 12 | H45: 1 | I45: No | J45: No | L45: =YEAR(A45) -> 2019 | M45: =IF(L45=2019,"Pre-COVID","COVID Period") -> Pre-COVID
A46: 43493 | B46: Antibiotic Prescriptions | C46: 15 | D46: 8.79 | E46: 131.85 | F46: 18 | G46: 5 | H46: 0.3 | I46: No | J46: No | L46: =YEAR(A46) -> 2019 | M46: =IF(L46=2019,"Pre-COVID","COVID Period") -> Pre-COVID
A47: 43493 | B47: Vitamins & Supplements | C47: 28 | D47: 11.74 | E47: 328.72 | F47: 38 | G47: 13 | H47: 1.5 | I47: No | J47: No | L47: =YEAR(A47) -> 2019 | M47: =IF(L47=2019,"Pre-COVID","COVID Period") -> Pre-COVID
A48: 43493 | B48: Simple Masks | C48: 10 | D48: 0.63 | E48: 6.3 | F48: 16 | G48: 8 | H48: 0.7 | I48: No | J48: No | L48: =YEAR(A48) -> 2019 | M48: =IF(L48=2019,"Pre-COVID","COVID Period") -> Pre-COVID
A49: 43493 | B49: KN95/FFP2 Masks | C49: 8 | D49: 1.32 | E49: 10.56 | F49: 12 | G49: 5 | H49: 1.4 | I49: No | J49: No | L49: =YEAR(A49) -> 2019 | M49: =IF(L49=2019,"Pre-COVID","COVID Period") -> Pre-COVID
A50: 43493 | B50: Antiseptic / Alcohol | C50: 9 | D50: 4.06 | E50: 36.54 | F50: 13 | G50: 5 | H50: 1.7 | I50: No | J50: No | L50: =YEAR(A50) -> 2019 | M50: =IF(L50=2019,"Pre-COVID","COVID Period") -> Pre-COVID
A51: 43493 | B51: Hand Gloves | C51: 5 | D51: 5.33 | E51: 26.65 | F51: 6 | G51: 1 | H51: 0.7 | I51: No | J51: No | L51: =YEAR(A51) -> 2019 | M51: =IF(L51=2019,"Pre-COVID","COVID Period") -> Pre-COVID
... A103: 43521 | B103: Hand Gloves | C103: 2 | D103: 5.7 | E103: 11.4 | F103: 3 | G103: 1 | H103: 2 | I103: No | J103: No | L103: =YEAR(A103) -> 2019 | M103: =IF(L103=2019,"Pre-COVID","COVID Period") -> Pre-COVID
A104: 43521 | B104: COVID Self Tests | C104: 1 | D104: 4.66 | E104: 4.66 | F104: 3 | G104: 2 | H104: 0.6 | I104: Yes | J104: No | K104: COVID-related demand spike | L104: =YEAR(A104) -> 2019 | M104: =IF(L104=2019,"Pre-COVID","COVID Period") -> Pre-COVID
A105: 43521 | B105: Pharmacy COVID Test Service | C105: 0 | D105: 15.16 | E105: 0 | F105: 3 | G105: 3 | H105: 0.7 | I105: No | J105: No | L105: =YEAR(A105) -> 2019 | M105: =IF(L105=2019,"Pre-COVID","COVID Period") -> Pre-COVID
A106: 43528 | B106: Adult Productive Cough Syrup | C106: 29 | D106: 7.09 | E106: 205.61 | F106: 42 | G106: 17 | H106: 0.8 | I106: No | J106: No | L106: =YEAR(A106) -> 2019 | M106: =IF(L106=2019,"Pre-COVID","COVID Period") -> Pre-COVID
A107: 43528 | B107: Adult Dry Cough Syrup | C107: 18 | D107: 7.11 | E107: 127.98 | F107: 29 | G107: 12 | H107: 1 | I107: No | J107: No | L107: =YEAR(A107) -> 2019 | M107: =IF(L107=2019,"Pre-COVID","COVID Period") -> Pre-COVID
A108: 43528 | B108: Children's Productive Cough Syrup | C108: 11 | D108: 5.71 | E108: 62.81 | F108: 13 | G108: 3 | H108: 0.4 | I108: No | J108: No | L108: =YEAR(A108) -> 2019 | M108: =IF(L108=2019,"Pre-COVID","COVID Period") -> Pre-COVID
A109: 43528 | B109: Children's Dry Cough Syrup | C109: 14 | D109: 6.41 | E109: 89.74 | F109: 17 | G109: 5 | H109: 0.9 | I109: No | J109: No | L109: =YEAR(A109) -> 2019 | M109: =IF(L109=2019,"Pre-COVID","COVID Period") -> Pre-COVID
A110: 43528 | B110: Cough Lozenges | C110: 25 | D110: 3.2 | E110: 80 | F110: 26 | G110: 1 | H110: 0.8 | I110: No | J110: No | L110: =YEAR(A110) -> 2019 | M110: =IF(L110=2019,"Pre-COVID","COVID Period") -> Pre-COVID
A111: 43528 | B111: Antibiotic Prescriptions | C111: 18 | D111: 8.9 | E111: 160.2 | F111: 26 | G111: 9 | H111: 0.1 | I111: No | J111: No | L111: =YEAR(A111) -> 2019 | M111: =IF(L111=2019,"Pre-COVID","COVID Period") -> Pre-COVID
A112: 43528 | B112: Vitamins & Supplements | C112: 19 | D112: 11.33 | E112: 215.27 | F112: 24 | G112: 8 | H112: 0.4 | I112: No | J112: No | L112: =YEAR(A112) -> 2019 | M112: =IF(L112=2019,"Pre-COVID","COVID Period") -> Pre-COVID
A113: 43528 | B113: Simple Masks | C113: 10 | D113: 0.68 | E113: 6.8 | F113: 16 | G113: 7 | H113: 0.4 | I113: No | J113: No | L113: =YEAR(A113) -> 2019 | M113: =IF(L113=2019,"Pre-COVID","COVID Period") -> Pre-COVID
A114: 43528 | B114: KN95/FFP2 Masks | C114: 7 | D114: 1.33 | E114: 9.31 | F114: 9 | G114: 2 | H114: 1.3 | I114: No | J114: No | L114: =YEAR(A114) -> 2019 | M114: =IF(L114=2019,"Pre-COVID","COVID Period") -> Pre-COVID
A115: 43528 | B115: Antiseptic / Alcohol | C115: 8 | D115: 4.18 | E115: 33.44 | F115: 10 | G115: 4 | H115: 0.2 | I115: No | J115: No | L115: =YEAR(A115) -> 2019 | M115: =IF(L115=2019,"Pre-COVID","COVID Period") -> Pre-COVID
...

Sheet Dashboard
A1: Pharmacy COVID-19 Operations Dashboard
A2: Synthetic portfolio project | Weekly data 2019–2022 | Selected OTC, prescription-support and COVID-related pharmacy categories
A4: Total Revenue | C4: Units Sold | E4: Out-of-Stock | G4: Avg Supplier Delay | I4: Demand Spikes | K4: Categories | M4: Period
A5: 230248.17 | C5: 42397 | E5: 74 | G5: 1.8239275 | I5: 781 | K5: 13 | M5: 2019–2022
A7: 2019–2022 data | C7: 2019–2022 data | E7: 2019–2022 data | G7: 2019–2022 data | I7: 2019–2022 data | K7: 2019–2022 data | M7: Weekly records
A9: Demand & Revenue Trend | I9: Operational Pressure
A27: Executive Insights & Recommended Actions
A28: Demand Spike Protective products and testing-related services increased strongly after early 2020. Track these separately from normal seasonal demand. | E28: Stock Pressure Out-of-stock incidents became visible in fast-moving COVID-related products. Minimum stock thresholds would help reduce risk. | I28: Supplier Delay Supplier delays increased during high-demand periods. Backup suppliers and proactive follow-up would improve readiness. | L28: Portfolio Value This project connects pharmacy operations experience with Excel, Power BI storytelling, KPI design and business recommendations.
A36: Disclaimer: Synthetic and anonymized portfolio dataset. Figures do not represent real pharmacy financial or patient data.

Sheet Yearly Summary
A1: Year | B1: Revenue | C1: Units Sold | D1: Out-of-Stock Incidents | E1: Demand Spike Records | F1: Avg Supplier Delay | G1: Revenue Share
A2: 2019 | B2: =SUMIFS(Data!$E$2:$E$2705,Data!$L$2:$L$2705,A2) -> 46281.22 | C2: =SUMIFS(Data!$C$2:$C$2705,Data!$L$2:$L$2705,A2) -> 7593 | D2: =COUNTIFS(Data!$L$2:$L$2705,A2,Data!$J$2:$J$2705,"Yes") -> 17 | E2: =COUNTIFS(Data!$L$2:$L$2705,A2,Data!$I$2:$I$2705,"Yes") -> 29 | F2: =SUMIFS(Data!$H$2:$H$2705,Data!$L$2:$L$2705,A2)/COUNTIFS(Data!$L$2:$L$2705,A2) -> 0.79497041 | G2: =B2/SUM($B$2:$B$5) -> 0.20100581
A3: 2020 | B3: =SUMIFS(Data!$E$2:$E$2705,Data!$L$2:$L$2705,A3) -> 64996.06 | C3: =SUMIFS(Data!$C$2:$C$2705,Data!$L$2:$L$2705,A3) -> 12715 | D3: =COUNTIFS(Data!$L$2:$L$2705,A3,Data!$J$2:$J$2705,"Yes") -> 13 | E3: =COUNTIFS(Data!$L$2:$L$2705,A3,Data!$I$2:$I$2705,"Yes") -> 244 | F3: =SUMIFS(Data!$H$2:$H$2705,Data!$L$2:$L$2705,A3)/COUNTIFS(Data!$L$2:$L$2705,A3) -> 2.2072485 | G3: =B3/SUM($B$2:$B$5) -> 0.28228698
A4: 2021 | B4: =SUMIFS(Data!$E$2:$E$2705,Data!$L$2:$L$2705,A4) -> 65753.72 | C4: =SUMIFS(Data!$C$2:$C$2705,Data!$L$2:$L$2705,A4) -> 12479 | D4: =COUNTIFS(Data!$L$2:$L$2705,A4,Data!$J$2:$J$2705,"Yes") -> 16 | E4: =COUNTIFS(Data!$L$2:$L$2705,A4,Data!$I$2:$I$2705,"Yes") -> 341 | F4: =SUMIFS(Data!$H$2:$H$2705,Data!$L$2:$L$2705,A4)/COUNTIFS(Data!$L$2:$L$2705,A4) -> 2.3 | G4: =B4/SUM($B$2:$B$5) -> 0.2855776
A5: 2022 | B5: =SUMIFS(Data!$E$2:$E$2705,Data!$L$2:$L$2705,A5) -> 53217.17 | C5: =SUMIFS(Data!$C$2:$C$2705,Data!$L$2:$L$2705,A5) -> 9610 | D5: =COUNTIFS(Data!$L$2:$L$2705,A5,Data!$J$2:$J$2705,"Yes") -> 28 | E5: =COUNTIFS(Data!$L$2:$L$2705,A5,Data!$I$2:$I$2705,"Yes") -> 167 | F5: =SUMIFS(Data!$H$2:$H$2705,Data!$L$2:$L$2705,A5)/COUNTIFS(Data!$L$2:$L$2705,A5) -> 1.9934911 | G5: =B5/SUM($B$2:$B$5) -> 0.23112961
A6: Total / Avg | B6: =SUM(B2:B5) -> 230248.17 | C6: =SUM(C2:C5) -> 42397 | D6: =SUM(D2:D5) -> 74 | E6: =SUM(E2:E5) -> 781 | F6: =AVERAGE(F2:F5) -> 1.8239275 | G6: =SUM(G2:G5) -> 1

Sheet Category Summary
A1: Category | B1: Revenue | C1: Units Sold | D1: Out-of-Stock Incidents | E1: Demand Spike Records | F1: Avg Supplier Delay | G1: 2019 Units | H1: Avg 2020-2022 Units | I1: Demand Growth %
A2: Vitamins & Supplements | B2: =SUMIFS(Data!$E$2:$E$2705,Data!$B$2:$B$2705,A2) -> 60378.6 | C2: =SUMIFS(Data!$C$2:$C$2705,Data!$B$2:$B$2705,A2) -> 5216 | D2: =COUNTIFS(Data!$B$2:$B$2705,A2,Data!$J$2:$J$2705,"Yes") -> 1 | E2: =COUNTIFS(Data!$B$2:$B$2705,A2,Data!$I$2:$I$2705,"Yes") -> 39 | F2: =SUMIFS(Data!$H$2:$H$2705,Data!$B$2:$B$2705,A2)/COUNTIFS(Data!$B$2:$B$2705,A2) -> 1.3774038 | G2: =SUMIFS(Data!$C$2:$C$2705,Data!$B$2:$B$2705,A2,Data!$L$2:$L$2705,2019) -> 1065 | H2: =(SUMIFS(Data!$C$2:$C$2705,Data!$B$2:$B$2705,A2,Data!$L$2:$L$2705,2020)+SUMIFS(Data!$C$2:$C$2705,Data!$B$2:$B$2705,A2,Data!$L$2:$L$2705,2021)+SUMIFS(Data!$C$2:$C$2705,Data!$B$2:$B$2705,A2,Data!$L$2:$L$2705,2022))/3 -> 1383.6667 | I2: =IF(G2=0,"",(H2/G2)-1) -> 0.29921753
A3: Adult Productive Cough Syrup | B3: =SUMIFS(Data!$E$2:$E$2705,Data!$B$2:$B$2705,A3) -> 28996.92 | C3: =SUMIFS(Data!$C$2:$C$2705,Data!$B$2:$B$2705,A3) -> 4234 | D3: =COUNTIFS(Data!$B$2:$B$2705,A3,Data!$J$2:$J$2705,"Yes") -> 0 | E3: =COUNTIFS(Data!$B$2:$B$2705,A3,Data!$I$2:$I$2705,"Yes") -> 7 | F3: =SUMIFS(Data!$H$2:$H$2705,Data!$B$2:$B$2705,A3)/COUNTIFS(Data!$B$2:$B$2705,A3) -> 1.4028846 | G3: =SUMIFS(Data!$C$2:$C$2705,Data!$B$2:$B$2705,A3,Data!$L$2:$L$2705,2019) -> 984 | H3: =(SUMIFS(Data!$C$2:$C$2705,Data!$B$2:$B$2705,A3,Data!$L$2:$L$2705,2020)+SUMIFS(Data!$C$2:$C$2705,Data!$B$2:$B$2705,A3,Data!$L$2:$L$2705,2021)+SUMIFS(Data!$C$2:$C$2705,Data!$B$2:$B$2705,A3,Data!$L$2:$L$2705,2022))/3 -> 1083.3333 | I3: =IF(G3=0,"",(H3/G3)-1) -> 0.10094851
A4: Adult Dry Cough Syrup | B4: =SUMIFS(Data!$E$2:$E$2705,Data!$B$2:$B$2705,A4) -> 25622.29 | C4: =SUMIFS(Data!$C$2:$C$2705,Data!$B$2:$B$2705,A4) -> 3592 | D4: =COUNTIFS(Data!$B$2:$B$2705,A4,Data!$J$2:$J$2705,"Yes") -> 2 | E4: =COUNTIFS(Data!$B$2:$B$2705,A4,Data!$I$2:$I$2705,"Yes") -> 3 | F4: =SUMIFS(Data!$H$2:$H$2705,Data!$B$2:$B$2705,A4)/COUNTIFS(Data!$B$2:$B$2705,A4) -> 1.2831731 | G4: =SUMIFS(Data!$C$2:$C$2705,Data!$B$2:$B$2705,A4,Data!$L$2:$L$2705,2019) -> 813 | H4: =(SUMIFS(Data!$C$2:$C$2705,Data!$B$2:$B$2705,A4,Data!$L$2:$L$2705,2020)+SUMIFS(Data!$C$2:$C$2705,Data!$B$2:$B$2705,A4,Data!$L$2:$L$2705,2021)+SUMIFS(Data!$C$2:$C$2705,Data!$B$2:$B$2705,A4,Data!$L$2:$L$2705,2022))/3 -> 926.33333 | I4: =IF(G4=0,"",(H4/G4)-1) -> 0.13940139
A5: Antibiotic Prescriptions | B5: =SUMIFS(Data!$E$2:$E$2705,Data!$B$2:$B$2705,A5) -> 25361.02 | C5: =SUMIFS(Data!$C$2:$C$2705,Data!$B$2:$B$2705,A5) -> 2972 | D5: =COUNTIFS(Data!$B$2:$B$2705,A5,Data!$J$2:$J$2705,"Yes") -> 2 | E5: =COUNTIFS(Data!$B$2:$B$2705,A5,Data!$I$2:$I$2705,"Yes") -> 2 | F5: =SUMIFS(Data!$H$2:$H$2705,Data!$B$2:$B$2705,A5)/COUNTIFS(Data!$B$2:$B$2705,A5) -> 1.3701923 | G5: =SUMIFS(Data!$C$2:$C$2705,Data!$B$2:$B$2705,A5,Data!$L$2:$L$2705,2019) -> 705 | H5: =(SUMIFS(Data!$C$2:$C$2705,Data!$B$2:$B$2705,A5,Data!$L$2:$L$2705,2020)+SUMIFS(Data!$C$2:$C$2705,Data!$B$2:$B$2705,A5,Data!$L$2:$L$2705,2021)+SUMIFS(Data!$C$2:$C$2705,Data!$B$2:$B$2705,A5,Data!$L$2:$L$2705,2022))/3 -> 755.66667 | I5: =IF(G5=0,"",(H5/G5)-1) -> 0.071867612
A6: Cough Lozenges | B6: =SUMIFS(Data!$E$2:$E$2705,Data!$B$2:$B$2705,A6) -> 18894.55 | C6: =SUMIFS(Data!$C$2:$C$2705,Data!$B$2:$B$2705,A6) -> 5865 | D6: =COUNTIFS(Data!$B$2:$B$2705,A6,Data!$J$2:$J$2705,"Yes") -> 0 | E6: =COUNTIFS(Data!$B$2:$B$2705,A6,Data!$I$2:$I$2705,"Yes") -> 1 | F6: =SUMIFS(Data!$H$2:$H$2705,Data!$B$2:$B$2705,A6)/COUNTIFS(Data!$B$2:$B$2705,A6) -> 1.3995192 | G6: =SUMIFS(Data!$C$2:$C$2705,Data!$B$2:$B$2705,A6,Data!$L$2:$L$2705,2019) -> 1357 | H6: =(SUMIFS(Data!$C$2:$C$2705,Data!$B$2:$B$2705,A6,Data!$L$2:$L$2705,2020)+SUMIFS(Data!$C$2:$C$2705,Data!$B$2:$B$2705,A6,Data!$L$2:$L$2705,2021)+SUMIFS(Data!$C$2:$C$2705,Data!$B$2:$B$2705,A6,Data!$L$2:$L$2705,2022))/3 -> 1502.6667 | I6: =IF(G6=0,"",(H6/G6)-1) -> 0.10734463
A7: Antiseptic / Alcohol | B7: =SUMIFS(Data!$E$2:$E$2705,Data!$B$2:$B$2705,A7) -> 18482 | C7: =SUMIFS(Data!$C$2:$C$2705,Data!$B$2:$B$2705,A7) -> 4383 | D7: =COUNTIFS(Data!$B$2:$B$2705,A7,Data!$J$2:$J$2705,"Yes") -> 6 | E7: =COUNTIFS(Data!$B$2:$B$2705,A7,Data!$I$2:$I$2705,"Yes") -> 122 | F7: =SUMIFS(Data!$H$2:$H$2705,Data!$B$2:$B$2705,A7)/COUNTIFS(Data!$B$2:$B$2705,A7) -> 2.5370192 | G7: =SUMIFS(Data!$C$2:$C$2705,Data!$B$2:$B$2705,A7,Data!$L$2:$L$2705,2019) -> 417 | H7: =(SUMIFS(Data!$C$2:$C$2705,Data!$B$2:$B$2705,A7,Data!$L$2:$L$2705,2020)+SUMIFS(Data!$C$2:$C$2705,Data!$B$2:$B$2705,A7,Data!$L$2:$L$2705,2021)+SUMIFS(Data!$C$2:$C$2705,Data!$B$2:$B$2705,A7,Data!$L$2:$L$2705,2022))/3 -> 1322 | I7: =IF(G7=0,"",(H7/G7)-1) -> 2.1702638
A8: Children's Dry Cough Syrup | B8: =SUMIFS(Data!$E$2:$E$2705,Data!$B$2:$B$2705,A8) -> 14820.34 | C8: =SUMIFS(Data!$C$2:$C$2705,Data!$B$2:$B$2705,A8) -> 2376 | D8: =COUNTIFS(Data!$B$2:$B$2705,A8,Data!$J$2:$J$2705,"Yes") -> 2 | E8: =COUNTIFS(Data!$B$2:$B$2705,A8,Data!$I$2:$I$2705,"Yes") -> 1 | F8: =SUMIFS(Data!$H$2:$H$2705,Data!$B$2:$B$2705,A8)/COUNTIFS(Data!$B$2:$B$2705,A8) -> 1.3456731 | G8: =SUMIFS(Data!$C$2:$C$2705,Data!$B$2:$B$2705,A8,Data!$L$2:$L$2705,2019) -> 543 | H8: =(SUMIFS(Data!$C$2:$C$2705,Data!$B$2:$B$2705,A8,Data!$L$2:$L$2705,2020)+SUMIFS(Data!$C$2:$C$2705,Data!$B$2:$B$2705,A8,Data!$L$2:$L$2705,2021)+SUMIFS(Data!$C$2:$C$2705,Data!$B$2:$B$2705,A8,Data!$L$2:$L$2705,2022))/3 -> 611 | I8: =IF(G8=0,"",(H8/G8)-1) -> 0.1252302
A9: Children's Productive Cough Syrup | B9: =SUMIFS(Data!$E$2:$E$2705,Data!$B$2:$B$2705,A9) -> 14108.31 | C9: =SUMIFS(Data!$C$2:$C$2705,Data!$B$2:$B$2705,A9) -> 2377 | D9: =COUNTIFS(Data!$B$2:$B$2705,A9,Data!$J$2:$J$2705,"Yes") -> 2 | E9: =COUNTIFS(Data!$B$2:$B$2705,A9,Data!$I$2:$I$2705,"Yes") -> 2 | F9: =SUMIFS(Data!$H$2:$H$2705,Data!$B$2:$B$2705,A9)/COUNTIFS(Data!$B$2:$B$2705,A9) -> 1.4629808 | G9: =SUMIFS(Data!$C$2:$C$2705,Data!$B$2:$B$2705,A9,Data!$L$2:$L$2705,2019) -> 556 | H9: =(SUMIFS(Data!$C$2:$C$2705,Data!$B$2:$B$2705,A9,Data!$L$2:$L$2705,2020)+SUMIFS(Data!$C$2:$C$2705,Data!$B$2:$B$2705,A9,Data!$L$2:$L$2705,2021)+SUMIFS(Data!$C$2:$C$2705,Data!$B$2:$B$2705,A9,Data!$L$2:$L$2705,2022))/3 -> 607 | I9: =IF(G9=0,"",(H9/G9)-1) -> 0.091726619
A10: Hand Gloves | B10: =SUMIFS(Data!$E$2:$E$2705,Data!$B$2:$B$2705,A10) -> 13925.12 | C10: =SUMIFS(Data!$C$2:$C$2705,Data!$B$2:$B$2705,A10) -> 2519 | D10: =COUNTIFS(Data!$B$2:$B$2705,A10,Data!$J$2:$J$2705,"Yes") -> 17 | E10: =COUNTIFS(Data!$B$2:$B$2705,A10,Data!$I$2:$I$2705,"Yes") -> 122 | F10: =SUMIFS(Data!$H$2:$H$2705,Data!$B$2:$B$2705,A10)/COUNTIFS(Data!$B$2:$B$2705,A10) -> 2.4086538 | G10: =SUMIFS(Data!$C$2:$C$2705,Data!$B$2:$B$2705,A10,Data!$L$2:$L$2705,2019) -> 257 | H10: =(SUMIFS(Data!$C$2:$C$2705,Data!$B$2:$B$2705,A10,Data!$L$2:$L$2705,2020)+SUMIFS(Data!$C$2:$C$2705,Data!$B$2:$B$2705,A10,Data!$L$2:$L$2705,2021)+SUMIFS(Data!$C$2:$C$2705,Data!$B$2:$B$2705,A10,Data!$L$2:$L$2705,2022))/3 -> 754 | I10: =IF(G10=0,"",(H10/G10)-1) -> 1.9338521
A11: KN95/FFP2 Masks | B11: =SUMIFS(Data!$E$2:$E$2705,Data!$B$2:$B$2705,A11) -> 4657.76 | C11: =SUMIFS(Data!$C$2:$C$2705,Data!$B$2:$B$2705,A11) -> 3434 | D11: =COUNTIFS(Data!$B$2:$B$2705,A11,Data!$J$2:$J$2705,"Yes") -> 8 | E11: =COUNTIFS(Data!$B$2:$B$2705,A11,Data!$I$2:$I$2705,"Yes") -> 122 | F11: =SUMIFS(Data!$H$2:$H$2705,Data!$B$2:$B$2705,A11)/COUNTIFS(Data!$B$2:$B$2705,A11) -> 2.6644231 | G11: =SUMIFS(Data!$C$2:$C$2705,Data!$B$2:$B$2705,A11,Data!$L$2:$L$2705,2019) -> 354 | H11: =(SUMIFS(Data!$C$2:$C$2705,Data!$B$2:$B$2705,A11,Data!$L$2:$L$2705,2020)+SUMIFS(Data!$C$2:$C$2705,Data!$B$2:$B$2705,A11,Data!$L$2:$L$2705,2021)+SUMIFS(Data!$C$2:$C$2705,Data!$B$2:$B$2705,A11,Data!$L$2:$L$2705,2022))/3 -> 1026.6667 | I11: =IF(G11=0,"",(H11/G11)-1) -> 1.9001883
A12: Simple Masks | B12: =SUMIFS(Data!$E$2:$E$2705,Data!$B$2:$B$2705,A12) -> 3442.3 | C12: =SUMIFS(Data!$C$2:$C$2705,Data!$B$2:$B$2705,A12) -> 5277 | D12: =COUNTIFS(Data!$B$2:$B$2705,A12,Data!$J$2:$J$2705,"Yes") -> 4 | E12: =COUNTIFS(Data!$B$2:$B$2705,A12,Data!$I$2:$I$2705,"Yes") -> 122 | F12: =SUMIFS(Data!$H$2:$H$2705,Data!$B$2:$B$2705,A12)/COUNTIFS(Data!$B$2:$B$2705,A12) -> 2.4802885 | G12: =SUMIFS(Data!$C$2:$C$2705,Data!$B$2:$B$2705,A12,Data!$L$2:$L$2705,2019) -> 513 | H12: =(SUMIFS(Data!$C$2:$C$2705,Data!$B$2:$B$2705,A12,Data!$L$2:$L$2705,2020)+SUMIFS(Data!$C$2:$C$2705,Data!$B$2:$B$2705,A12,Data!$L$2:$L$2705,2021)+SUMIFS(Data!$C$2:$C$2705,Data!$B$2:$B$2705,A12,Data!$L$2:$L$2705,2022))/3 -> 1588 | I12: =IF(G12=0,"",(H12/G12)-1) -> 2.0955166
A13: Pharmacy COVID Test Service | B13: =SUMIFS(Data!$E$2:$E$2705,Data!$B$2:$B$2705,A13) -> 1215.61 | C13: =SUMIFS(Data!$C$2:$C$2705,Data!$B$2:$B$2705,A13) -> 81 | D13: =COUNTIFS(Data!$B$2:$B$2705,A13,Data!$J$2:$J$2705,"Yes") -> 6 | E13: =COUNTIFS(Data!$B$2:$B$2705,A13,Data!$I$2:$I$2705,"Yes") -> 125 | F13: =SUMIFS(Data!$H$2:$H$2705,Data!$B$2:$B$2705,A13)/COUNTIFS(Data!$B$2:$B$2705,A13) -> 2.0163462 | G13: =SUMIFS(Data!$C$2:$C$2705,Data!$B$2:$B$2705,A13,Data!$L$2:$L$2705,2019) -> 16 | H13: =(SUMIFS(Data!$C$2:$C$2705,Data!$B$2:$B$2705,A13,Data!$L$2:$L$2705,2020)+SUMIFS(Data!$C$2:$C$2705,Data!$B$2:$B$2705,A13,Data!$L$2:$L$2705,2021)+SUMIFS(Data!$C$2:$C$2705,Data!$B$2:$B$2705,A13,Data!$L$2:$L$2705,2022))/3 -> 21.666667 | I13: =IF(G13=0,"",(H13/G13)-1) -> 0.35416667
A14: COVID Self Tests | B14: =SUMIFS(Data!$E$2:$E$2705,Data!$B$2:$B$2705,A14) -> 343.35 | C14: =SUMIFS(Data!$C$2:$C$2705,Data!$B$2:$B$2705,A14) -> 71 | D14: =COUNTIFS(Data!$B$2:$B$2705,A14,Data!$J$2:$J$2705,"Yes") -> 24 | E14: =COUNTIFS(Data!$B$2:$B$2705,A14,Data!$I$2:$I$2705,"Yes") -> 113 | F14: =SUMIFS(Data!$H$2:$H$2705,Data!$B$2:$B$2705,A14)/COUNTIFS(Data!$B$2:$B$2705,A14) -> 1.9625 | G14: =SUMIFS(Data!$C$2:$C$2705,Data!$B$2:$B$2705,A14,Data!$L$2:$L$2705,2019) -> 13 | H14: =(SUMIFS(Data!$C$2:$C$2705,Data!$B$2:$B$2705,A14,Data!$L$2:$L$2705,2020)+SUMIFS(Data!$C$2:$C$2705,Data!$B$2:$B$2705,A14,Data!$L$2:$L$2705,2021)+SUMIFS(Data!$C$2:$C$2705,Data!$B$2:$B$2705,A14,Data!$L$2:$L$2705,2022))/3 -> 19.333333 | I14: =IF(G14=0,"",(H14/G14)-1) -> 0.48717949

Sheet Insights
A1: Insight Type | B1: Finding | C1: Operational meaning
A2: Demand spike | B2: Protective products and testing-related categories increased after early 2020. | C2: The pharmacy needed closer monitoring of fast-moving health-crisis items.
A3: Revenue mix | B3: Vitamins & supplements remained a strong revenue category across the period. | C3: Prevention and immune-support products became commercially important.
A4: Stock pressure | B4: Out-of-stock incidents were visible in COVID-related and protective categories. | C4: Minimum stock thresholds could reduce lost sales and customer frustration.
A5: Supplier reliability | B5: Average supplier delays increased during the main COVID period. | C5: Supplier follow-up and backup sourcing would support service readiness.
A6: Planning | B6: COVID demand should be separated from normal seasonal pharmacy demand. | C6: This avoids overestimating future baseline demand after crisis periods.
